<?xml version="1.0"?>
<robot name="aubo_C3">
  <dh_type type="modified"/>
  <safety_para singularity_consistent="0.02 0.01 10 0.2 0.045 10"/>
  <friction_coeff value="0.5"/>
  <link name="aubo_base">
    <inertial>
      <origin xyz="0.000149 -0.0004 0.0346" rpy="0 0 0" />
      <mass value="1.365846" />
      <inertia ixx="0.002801" ixy="-0.000001" ixz="0.000002" iyy="0.002763" iyz="0.000011" izz="0.003837" />
    </inertial>
    <visual>
      <origin xyz="0 0 0" rpy="0 0 0" />
      <geometry>
        <mesh filename="package://aubo_description/meshes/aubo_C3/visual/link0.DAE" />
      </geometry>
      <material name="">
        <color rgba="1 1 1 1" />
      </material>
    </visual>
    <collision>
      <origin xyz="0 0 0" rpy="0 0 0" />
      <geometry>
        <mesh filename="package://aubo_description/meshes/aubo_C3/collision/link0.STL" />
      </geometry>
    </collision>
  </link>

  <link name="shoulder_Link">
    <inertial>
      <origin xyz="-0.000016 0.001852 -0.015716" rpy="0 0 0" />
      <mass value="3.2573" />
      <inertia ixx="0.005717" ixy="0.000001" ixz="0.000004" iyy="0.005636" iyz="-0.000131" izz="0.003863" />
    </inertial>
    <visual>
      <origin xyz="0 0 0" rpy="0 0 0" />
      <geometry>
        <mesh filename="package://aubo_description/meshes/aubo_C3/visual/link1.DAE" />
      </geometry>
      <material name="">
        <color rgba="1 1 1 1" />
      </material>
    </visual>
    <collision>
      <origin xyz="0 0 0" rpy="0 0 0" />
      <geometry>
        <mesh filename="package://aubo_description/meshes/aubo_C3/collision/link1.STL" />
      </geometry>
    </collision>
  </link>

  <joint name="shoulder_joint" type="revolute">
    <origin xyz="0 0 0.157" rpy="0 0 3.1415926535897932384626433832795" />
    <parent link="aubo_base" />
    <child link="shoulder_Link" />
    <axis xyz="0 0 1" />
    <limit lower="-3.05" upper="3.05" effort="61" start_stop="102" velocity="3.1104877758314784539234092903757" />
    <property inertia="0" damping="0" stiffness="0" offset="0" motor_constant="7.03" ratio="101" protect_max_torque="50.0" equa_inertia="0.5" collision_detection_para = "50 50 30 20"/>
  </joint>

  <link name="upperArm_Link">
    <inertial>
      <origin xyz="0.113925 -0.000006 -0.006424" rpy="0 0 0" />
      <mass value="6.116851" />
      <inertia ixx="0.009999" ixy="0.000018" ixz="-0.000214" iyy="0.106325" iyz="0.000003" izz="0.102883" />
    </inertial>
    <visual>
      <origin xyz="0 0 0" rpy="0 0 0" />
      <geometry>
        <mesh filename="package://aubo_description/meshes/aubo_C3/visual/link2.DAE" />
      </geometry>
      <material name="">
        <color rgba="1 1 1 1" />
      </material>
    </visual>
    <collision>
      <origin xyz="0 0 0" rpy="0 0 0" />
      <geometry>
        <mesh filename="package://aubo_description/meshes/aubo_C3/collision/link2.STL" />
      </geometry>
    </collision>
  </link>

  <joint name="upperArm_joint" type="revolute">
    <origin xyz="0 0.119 0" rpy="-1.5707963267948966192313216916398 -1.5707963267948966192313216916398 0" />
    <parent link="shoulder_Link" />
    <child link="upperArm_Link" />
    <axis xyz="0 0 1" />
    <limit lower="-3.05" upper="3.05" effort="61" start_stop="102" velocity="3.1104877758314784539234092903757" />
    <property inertia="0" damping="0" stiffness="0" offset="0" motor_constant="7.03" ratio="101" protect_max_torque="50.0" equa_inertia="0.5" collision_detection_para = "50 50 30 20"/>
  </joint>

  <link name="foreArm_Link">
    <inertial>
      <origin xyz="0.201115 -0.000036 0.093625" rpy="0 0 0" />
      <mass value="2.351523" />
      <inertia ixx="0.00276" ixy="0.000003" ixz="0.000301" iyy="0.022363" iyz="0.000004" izz="0.021553" />
    </inertial>
    <visual>
      <origin xyz="0 0 0" rpy="0 0 0" />
      <geometry>
        <mesh filename="package://aubo_description/meshes/aubo_C3/visual/link3.DAE" />
      </geometry>
      <material name="">
        <color rgba="1 1 1 1" />
      </material>
    </visual>
    <collision>
      <origin xyz="0 0 0" rpy="0 0 0" />
      <geometry>
        <mesh filename="package://aubo_description/meshes/aubo_C3/collision/link3.STL" />
      </geometry>
    </collision>
  </link>

  <joint name="foreArm_joint" type="revolute">
    <origin xyz="0.266 0 0" rpy="-3.1415926535897932384626433832795 0 0" />
    <parent link="upperArm_Link" />
    <child link="foreArm_Link" />
    <axis xyz="0 0 1" />
    <limit lower="-3.05" upper="3.05" effort="49" start_stop="66" velocity="3.1104877758314784539234092903757" />
    <property inertia="0" damping="0" stiffness="0" offset="0" motor_constant="6.07" ratio="101" protect_max_torque="30.0" equa_inertia="0.25" collision_detection_para = "50 50 30 20"/>
  </joint>

  <link name="wrist1_Link">
    <inertial>
      <origin xyz="0.000038 0.011278 -0.001539" rpy="0 0 0" />
      <mass value="1.628022" />
      <inertia ixx="0.001951" ixy="0.000003" ixz="0.000001" iyy="0.001154" iyz="-0.000042" izz="0.001931" />
    </inertial>
    <visual>
      <origin xyz="0 0 0" rpy="0 0 0" />
      <geometry>
        <mesh filename="package://aubo_description/meshes/aubo_C3/visual/link4.DAE" />
      </geometry>
      <material name="">
        <color rgba="1 1 1 1" />
      </material>
    </visual>
    <collision>
      <origin xyz="0 0 0" rpy="0 0 0" />
      <geometry>
        <mesh filename="package://aubo_description/meshes/aubo_C3/collision/link4.STL" />
      </geometry>
    </collision>
  </link>

  <joint name="wrist1_joint" type="revolute">
    <origin xyz="0.2565 0 0" rpy="3.1415926535897932384626433832795 0 1.5707963267948966192313216916398" />
    <parent link="foreArm_Link" />
    <child link="wrist1_Link" />
    <axis xyz="0 0 1" />
    <limit lower="-3.05" upper="3.05" effort="13.5" start_stop="34" velocity="3.1104877758314784539234092903757" />
    <property inertia="0" damping="0" stiffness="0" offset="0" motor_constant="5.895" ratio="101" protect_max_torque="8.0" equa_inertia="0.05" collision_detection_para = "50 50 30 20"/>
  </joint>

  <link name="wrist2_Link">
    <inertial>
      <origin xyz="-0.000038 -0.011278 -0.001539" rpy="0 0 0" />
      <mass value="1.628022" />
      <inertia ixx="0.001951" ixy="0.000003" ixz="-0.000001" iyy="0.001154" iyz="0.000042" izz="0.001931" />
    </inertial>
    <visual>
      <origin xyz="0 0 0" rpy="0 0 0" />
      <geometry>
        <mesh filename="package://aubo_description/meshes/aubo_C3/visual/link5.DAE" />
      </geometry>
      <material name="">
        <color rgba="1 1 1 1" />
      </material>
    </visual>
    <collision>
      <origin xyz="0 0 0" rpy="0 0 0" />
      <geometry>
        <mesh filename="package://aubo_description/meshes/aubo_C3/collision/link5.STL" />
      </geometry>
    </collision>
  </link>

  <joint name="wrist2_joint" type="revolute">
    <origin xyz="0 0.1025 0" rpy="-1.5707963267948966192313216916398 0 0" />
    <parent link="wrist1_Link" />
    <child link="wrist2_Link" />
    <axis xyz="0 0 1" />
    <limit lower="-3.05" upper="3.05" effort="13.5" start_stop="34" velocity="3.1104877758314784539234092903757" />
    <property inertia="0" damping="0" stiffness="0" offset="0" motor_constant="5.895" ratio="101" protect_max_torque="8.0" equa_inertia="0.05" collision_detection_para = "50 50 30 20"/>
  </joint>

  <link name="wrist3_Link">
    <inertial>
      <origin xyz="0.000022 0.0006 -0.017081" rpy="0 0 0" />
      <mass value="0.1978" />
      <inertia ixx="0.000118" ixy="0" ixz="0" iyy="0.000112" iyz="0.000001" izz="0.000184" />
    </inertial>
    <visual>
      <origin xyz="0 0 0" rpy="0 0 0" />
      <geometry>
        <mesh filename="package://aubo_description/meshes/aubo_C3/visual/link6.DAE" />
      </geometry>
      <material name="">
        <color rgba="1 1 1 1" />
      </material>
    </visual>
    <collision>
      <origin xyz="0 0 0" rpy="0 0 0" />
      <geometry>
        <mesh filename="package://aubo_description/meshes/aubo_C3/collision/link6.STL" />
      </geometry>
    </collision>
  </link>

  <joint name="wrist3_joint" type="revolute">
    <origin xyz="0 -0.094 0" rpy="1.5707963267948966192313216916398 0 0" />
    <parent link="wrist2_Link" />
    <child link="wrist3_Link" />
    <axis xyz="0 0 1" />
    <limit lower="-3.05" upper="3.05" effort="13.5" start_stop="34" velocity="3.1104877758314784539234092903757" />
    <property inertia="0" damping="0" stiffness="0" offset="0" motor_constant="5.895" ratio="101" protect_max_torque="1.0" equa_inertia="0.01" collision_detection_para = "50 50 30 20"/>
  </joint>

  <link name="world" />

  <joint name="world_joint" type="fixed">
    <parent link="world" />
    <child link = "aubo_base" />
    <origin xyz="0.0 0.0 0.0" rpy="0.0 0.0 0.0" />
  </joint>
</robot>
